Workbook
Name Slicer_Month1: #N/A
Name Slicer_Ngành_Hàng: #N/A
Name Slicer_Segment: #N/A

Sheet Customer Dashboard

Sheet Product Dashboard

Sheet Strategic Insights
A1: 📊 DATA STORYTELLING — INSIGHTS & STRATEGIC RECOMMENDATIONS
A4: 💰 Doanh Thu | B4: 📈 Lợi Nhuận | C4: 📊 Biên LN | D4: 🛒 Số Đơn | E4: 👥 Khách Hàng | F4: 💳 AOV
A5: 269,283,456 VNĐ | B5: 56,843,559 VNĐ | C5: 0.1743 | D5: 705 đơn | E5: 159 khách | F5: 381,962 VNĐ/đơn
A7: 🔍 KEY INSIGHTS — Phát hiện từ Dữ liệu
A8: Lĩnh vực | B8: Icon | C8: Phát hiện (Finding) | D8: Hàm ý (Implication) | E8: Hành động đề xuất (Action)
A9: 1 | B9: REVENUE | C9: 💰 | D9: Nhóm Trung thành + VIP = 68.7% tổng doanh thu (185M VNĐ) nhưng chỉ chiếm ~25% lượng khách (≈40 người) | E9: Nền kinh doanh phụ thuộc nặng vào nhóm nhỏ → rủi ro nếu 1-2 khách VIP rời bỏ | F9: Triển khai chương trình Loyalty riêng: tặng ưu tiên giao hàng, chiết khấu tích lũy, báo giá sớm
A10: 2 | C10: 📉 | D10: Nhóm Tiềm năng chỉ đóng góp 2.1% doanh thu (5.6M VNĐ) — thấp nhất trong tất cả phân khúc | E10: Khách đang 'thử nghiệm' nhưng chưa convert thành khách mua thường xuyên | F10: Tạo chương trình 'First Order Deal': giảm 5% cho đơn hàng 2 và 3 để tăng tần suất mua
A11: 3 | B11: PRODUCT | C11: 🏆 | D11: Top 1 doanh thu: Yến sào Seaweed CD vàng x6 hộp (~25.2M VNĐ) — gấp 3x sản phẩm thứ 3 | E11: Sản phẩm đang là 'cash cow' nhưng phụ thuộc 1 SKU gây rủi ro chuỗi cung ứng | F11: Mở rộng portfolio Yến sào (size khác, gói quà), đảm bảo tồn kho chiến lược ≥30 ngày
A12: 4 | C12: 💎 | D12: BC KAKA NANO X6 có margin cao nhất (~82%) nhưng doanh thu thấp (<2M VNĐ) | E12: Sản phẩm lãi cao nhưng chưa được đẩy mạnh — tiềm năng ẩn lớn | F12: Đẩy BC KAKA NANO vào bundle deals với sản phẩm bán chạy (ví dụ: Yến sào + BC KAKA)
A13: 5 | C13: ⚠️ | D13: Nhóm Giấy Vệ Sinh (GC + HM) có doanh thu cao nhưng margin thường thấp (~10-12%) | E13: Đang dùng sản phẩm thấp lợi nhuận để giữ doanh thu — không bền vững dài hạn | F13: Thương lượng lại giá nhập từ nhà cung cấp GC/HM hoặc tăng giá bán lẻ 3-5%
A14: 6 | B14: CUSTOMER | C14: 🎯 | D14: AOV trung bình = 381,962 VNĐ/đơn — phân hóa lớn giữa VIP và nhóm Mới/Tiềm năng | E14: Khách Mới mua ít, khách VIP mua nhiều hơn 4-5x — hành vi mua hoàn toàn khác nhau | F14: Phân tách chiến lược: upsell cho VIP/Trung thành, nurture sequence email/zalo cho nhóm Mới
A15: 7 | C15: 🔄 | D15: 159 khách / 705 đơn = trung bình 4.4 đơn/khách — tần suất mua tốt | E15: Nếu nâng được lên 5.5 đơn/khách, doanh thu có thể tăng thêm ~65M VNĐ (25%) mà không cần khách mới | F15: Tạo 'Subscription deals': ưu đãi đặt hàng định kỳ hàng tháng (tự động) giảm 3%
A16: 8 | B16: OPERATIONS | C16: 📦 | D16: Nhóm Thực Phẩm & Bánh Kẹo có doanh thu thấp nhưng số SKU nhiều → chi phí quản lý tồn kho cao | E16: Long-tail sản phẩm làm phân tán nguồn lực mà không tạo doanh thu đáng kể | F16: Áp dụng ABC Analysis: giữ top 20 SKU (80% doanh thu), cân nhắc loại bỏ/giảm SKU đáy
A18: 🚀 STRATEGIC RECOMMENDATIONS — Chiến lược Hành động
A19: PRIORITY 1 — DEFEND: Bảo vệ & Phát triển nhóm VIP + Trung thành
B20: ✔ Gọi điện/gặp mặt trực tiếp top 10 KH mỗi quý
B21: ✔ Cung cấp báo giá ưu tiên trước khi hàng về
B22: ✔ Tặng sample mới → tăng cơ hội cross-sell
B23: ✔ KPI: Giảm churn VIP xuống 0%, tăng AOV VIP thêm 10%
A24: PRIORITY 2 — GROW: Chuyển đổi nhóm Tiềm năng → Trung thành
B25: ✔ Email/Zalo workflow 4 tuần sau đơn đầu tiên
B26: ✔ Offer 'Bundle hàng dùng thường ngày' giảm 5%
B27: ✔ Assign 1 sale phụ trách follow-up nhóm này
B28: ✔ KPI: Tỷ lệ mua lần 2 trong 60 ngày ≥ 40%
A29: PRIORITY 3 — OPTIMIZE: Tối ưu hóa danh mục sản phẩm
B30: ✔ Loại bỏ SKU có margin <8% VÀ doanh thu <5M/quý
B31: ✔ Đẩy mạnh các sản phẩm margin >30%: BC KAKA, SmileNest
B32: ✔ Đàm phán giá nhập với top 3 nhà cung cấp
B33: ✔ KPI: Tăng gross margin từ 17.4% lên 20% trong 6 tháng
A34: PRIORITY 4 — SCALE: Mở rộng vào ngành hàng tiềm năng
B35: ✔ Khăn Giấy & Khăn Ướt: ngành hàng lớn nhất, cân nhắc thêm nhãn hiệu mới
B36: ✔ Bàn Chải & Răng Miệng: margin cao, B2B tiềm năng (spa, khách sạn, phòng khám)
B37: ✔ Yến sào: premium segment, có thể target khách hàng quà biếu/công ty
B38: ✔ KPI: Thêm 2 ngành hàng mới vào danh mục trong Q3
A40: 📅 TIMELINE — Lộ trình Thực hiện
A41: Thời điểm | B41: Hành động | C41: Người phụ trách | D41: Chỉ số đo lường | E41: Mục tiêu
A42: Tuần 1-2 | B42: Gọi điện/gặp top 10 KH VIP, xác nhận nhu cầu Q4 | C42: Sales Manager | D42: Số cuộc gọi thực hiện | E42: 10/10 KH
A43: Tuần 2-3 | B43: Thiết lập Loyalty Program: tích điểm, ưu đãi đặt hàng định kỳ | C43: Marketing | D43: Tỷ lệ đăng ký | E43: ≥ 60% KH VIP
A44: Tuần 3-4 | B44: Chạy campaign Zalo cho nhóm Tiềm năng (79 KH) | C44: Marketing | D44: Tỷ lệ mở tin / click | E44: Open rate ≥ 30%
A45: Tháng 2 | B45: ABC Analysis danh mục: xác định SKU cần loại bỏ | C45: Product Manager | D45: Số SKU cắt giảm | E45: Giảm 15% SKU đáy
...

Sheet Data Model
A1: STT | B1: Mã | C1: Hàng | D1: ĐVT | E1: Tiền Nhập | F1: SL Xuất KM | G1: SL Xuất | H1: Tiền Xuất | I1: Doanh Thu | J1: Ngày Xuất | K1: Khách hàng | L1: Segment | M1: Lợi Nhuận | N1: Tỷ lệ lợi nhuận | O1: Tổng số lượng bán | P1: % SL Khuyến mãi | Q1: Year | R1: Month | S1: Ngành Hàng
A2: 1 | B2: KV100 | C2: Khăn Napkin Toply 100 tờ x 48 gói | D2: Gói | E2: 691200 | F2: 0 | G2: 96 | H2: 1036800 | I2: =H2 -> 1036800 | J2: 45170 | K2: Xuân Bình - M.Hiệp | L2: =VLOOKUP(DataSales[[#This Row],[Khách hàng]],'RFM Table'!$A:$I,9,FALSE) -> Khách hàng VIP | M2: =I2-E2 -> 345600 | N2: 0.33333333 | O2: 96 | P2: 0 | Q2: 2023 | R2: =MONTH(DataSales[[#This Row],[Ngày Xuất]]) -> 9 | S2: Khăn Giấy
A3: 2 | B3: TLM | C3: Tẩy toilet Liên Minh (nguyên liệu nhập khẩu) x 12 chai | D3: Chai | E3: 800040 | F3: 0 | G3: 60 | H3: 1100040 | I3: =H3 -> 1100040 | J3: 45170 | K3: Xuân Bình - M.Hiệp | L3: =VLOOKUP(DataSales[[#This Row],[Khách hàng]],'RFM Table'!$A:$I,9,FALSE) -> Khách hàng VIP | M3: =I3-E3 -> 300000 | N3: 0.27271736 | O3: 60 | P3: 0 | Q3: 2023 | R3: =MONTH(DataSales[[#This Row],[Ngày Xuất]]) -> 9 | S3: Chăm Sóc Nhà Cửa
A4: 3 | B4: NG3600 | C4: Nước giặt Kimono 6 in 1 (tím) x 3,6kg x 4 bình | D4: Bình | E4: 365000 | F4: 0 | G4: 4 | H4: 480000 | I4: =H4 -> 480000 | J4: 45170 | K4: Bé Bắp - N.Mỹ | L4: =VLOOKUP(DataSales[[#This Row],[Khách hàng]],'RFM Table'!$A:$I,9,FALSE) -> Khách hàng Cần chú ý | M4: =I4-E4 -> 115000 | N4: 0.23958333 | O4: 4 | P4: 0 | Q4: 2023 | R4: =MONTH(DataSales[[#This Row],[Ngày Xuất]]) -> 9 | S4: Chăm Sóc Nhà Cửa
A5: 4 | B5: KV1002 | C5: Khăn Napkin TiOne nâu 100 tờ x 30 gói | D5: Gói | E5: 1296000 | F5: 0 | G5: 180 | H5: 1692000 | I5: =H5 -> 1692000 | J5: 45170 | K5: Căn tin BV Phổi( Chị Duyên) - BV phổi | L5: =VLOOKUP(DataSales[[#This Row],[Khách hàng]],'RFM Table'!$A:$I,9,FALSE) -> Khách hàng VIP | M5: =I5-E5 -> 396000 | N5: 0.23404255 | O5: 180 | P5: 0 | Q5: 2023 | R5: =MONTH(DataSales[[#This Row],[Ngày Xuất]]) -> 9 | S5: Khăn Giấy
A6: 5 | B6: BCTEM32 | C6: BCTE N32 (xe) x 12 x 30 hộp | D6: Cây | E6: 46800 | F6: 0 | G6: 6 | H6: 66000 | I6: =H6 -> 66000 | J6: 45170 | K6: MP Nhanh - M.Hiệp | L6: =VLOOKUP(DataSales[[#This Row],[Khách hàng]],'RFM Table'!$A:$I,9,FALSE) -> Khách hàng VIP | M6: =I6-E6 -> 19200 | N6: 0.29090909 | O6: 6 | P6: 0 | Q6: 2023 | R6: =MONTH(DataSales[[#This Row],[Ngày Xuất]]) -> 9 | S6: Bàn Chải & Răng Miệng
A7: 6 | B7: BCTEM35 | C7: BCTE N35 (búp bê) x 12 x 30 hộp | D7: Cây | E7: 46800 | F7: 0 | G7: 6 | H7: 66000 | I7: =H7 -> 66000 | J7: 45170 | K7: MP Nhanh - M.Hiệp | L7: =VLOOKUP(DataSales[[#This Row],[Khách hàng]],'RFM Table'!$A:$I,9,FALSE) -> Khách hàng VIP | M7: =I7-E7 -> 19200 | N7: 0.29090909 | O7: 6 | P7: 0 | Q7: 2023 | R7: =MONTH(DataSales[[#This Row],[Ngày Xuất]]) -> 9 | S7: Bàn Chải & Răng Miệng
A8: 7 | B8: BCTEN36 | C8: BCTE N36 (đồng hồ) x 18 x 20 hộp | D8: Cây | E8: 46800 | F8: 0 | G8: 6 | H8: 66000 | I8: =H8 -> 66000 | J8: 45170 | K8: MP Nhanh - M.Hiệp | L8: =VLOOKUP(DataSales[[#This Row],[Khách hàng]],'RFM Table'!$A:$I,9,FALSE) -> Khách hàng VIP | M8: =I8-E8 -> 19200 | N8: 0.29090909 | O8: 6 | P8: 0 | Q8: 2023 | R8: =MONTH(DataSales[[#This Row],[Ngày Xuất]]) -> 9 | S8: Bàn Chải & Răng Miệng
A9: 8 | B9: KU100 | C9: Khăn ướt Begin 100 tờ x 20 gói | D9: Gói | E9: 340000 | F9: 5 | G9: 20 | H9: 480000 | I9: =H9 -> 480000 | J9: 45170 | K9: MP Nhanh - M.Hiệp | L9: =VLOOKUP(DataSales[[#This Row],[Khách hàng]],'RFM Table'!$A:$I,9,FALSE) -> Khách hàng VIP | M9: =I9-E9 -> 140000 | N9: 0.29166667 | O9: 25 | P9: 0.2 | Q9: 2023 | R9: =MONTH(DataSales[[#This Row],[Ngày Xuất]]) -> 9 | S9: Khăn Ướt
A10: 10 | B10: KV320 | C10: Khăn Napkin Fairy 320 x 100 tờ x 48 gói | D10: Gói | E10: 528000 | F10: 0 | G10: 48 | H10: 576000 | I10: =H10 -> 576000 | J10: 45173 | K10: Chị Nga - HCL | L10: =VLOOKUP(DataSales[[#This Row],[Khách hàng]],'RFM Table'!$A:$I,9,FALSE) -> Khách hàng Trung thành | M10: =I10-E10 -> 48000 | N10: 0.083333333 | O10: 48 | P10: 0 | Q10: 2023 | R10: =MONTH(DataSales[[#This Row],[Ngày Xuất]]) -> 9 | S10: Khăn Giấy
A11: 11 | B11: KV320 | C11: Khăn Napkin Fairy 320 x 100 tờ x 48 gói | D11: Gói | E11: 1056000 | F11: 0 | G11: 96 | H11: 960000 | I11: =H11 -> 960000 | J11: 45173 | K11: Mỹ Nhân - N.Mỹ | L11: =VLOOKUP(DataSales[[#This Row],[Khách hàng]],'RFM Table'!$A:$I,9,FALSE) -> Khách hàng Trung thành | M11: =I11-E11 -> -96000 | N11: -0.1 | O11: 96 | P11: 0 | Q11: 2023 | R11: =MONTH(DataSales[[#This Row],[Ngày Xuất]]) -> 9 | S11: Khăn Giấy
A12: 12 | B12: KV100 | C12: Khăn Napkin Toply 100 tờ x 48 gói | D12: Gói | E12: 345600 | F12: 0 | G12: 48 | H12: 576000 | I12: =H12 -> 576000 | J12: 45173 | K12: Điện thoại Tuấn - N.Mỹ | L12: =VLOOKUP(DataSales[[#This Row],[Khách hàng]],'RFM Table'!$A:$I,9,FALSE) -> Khách hàng Cần chú ý | M12: =I12-E12 -> 230400 | N12: 0.4 | O12: 48 | P12: 0 | Q12: 2023 | R12: =MONTH(DataSales[[#This Row],[Ngày Xuất]]) -> 9 | S12: Khăn Giấy
A13: 16 | B13: A1K15 | C13: Kẹo bạc hà (chanh muối) Himalaya 15g x 12 gói x 12 hộp | D13: Hộp | E13: 120756 | F13: 0 | G13: 2 | H13: 112000 | I13: =H13 -> 112000 | J13: 45173 | K13: TT Hải Hà - HCL | L13: =VLOOKUP(DataSales[[#This Row],[Khách hàng]],'RFM Table'!$A:$I,9,FALSE) -> Khách hàng Cần chú ý | M13: =I13-E13 -> -8756 | N13: -0.078178571 | O13: 2 | P13: 0 | Q13: 2023 | R13: =MONTH(DataSales[[#This Row],[Ngày Xuất]]) -> 9 | S13: Thực Phẩm & Bánh Kẹo
... A706: 841 | B706: XX500 | C706: XÚC XÍCH TƯƠI XÔNG KHÓI 10 cây x 500g | D706: Gói | E706: 54000 | F706: 0 | G706: 2 | H706: 70000 | I706: =H706 -> 70000 | J706: 45260 | K706: Tú Kiều - T.Nghĩa | L706: =VLOOKUP(DataSales[[#This Row],[Khách hàng]],'RFM Table'!$A:$I,9,FALSE) -> Khách hàng Trung thành | M706: =I706-E706 -> 16000 | N706: 0.22857143 | O706: 2 | P706: 0 | Q706: 2023 | R706: =MONTH(DataSales[[#This Row],[Ngày Xuất]]) -> 11 | S706: Thực Phẩm & Bánh Kẹo

Sheet Product Pivot
J1: Row Labels | K1: Tổng Doanh Thu | M1: % KM Trung Bình | O1: Row Labels | P1: Số Đơn Hàng | S1: Row Labels | T1: Tổng Doanh Thu | Z1: =TEXT(VLOOKUP("Grand Total", J1:K11, 2, FALSE), "#,##0 ""VNĐ""") -> 269,283,456 VNĐ | AA1: Row Labels | AB1: Sum of Doanh Thu | AI1: Values | AO1: Values | AS1: Sản phẩm | AT1: Margin% | AU1: Doanh Thu | BA1: Row Labels | BB1: Sum of Doanh Thu | BH1: Phân khúc | BI1: Revenue Share % | BJ1: LN/Khách (VNĐ)
J2: Khách hàng Cần chú ý | K2: 52659100 | M2: 0.046250101 | O2: Khách hàng Cần chú ý | P2: 127 | S2: Khách hàng Cần chú ý | T2: 52659100 | Z2: =TEXT(VLOOKUP("Grand Total", J12:L22, 2, FALSE), "#,##0 ""VNĐ""") -> 56,843,559 VNĐ | AA2: Bánh gạo TE Happy Bites Chuối 50g x 12 hộp | AB2: 5540000 | AH2: Row Labels | AI2: Sum of Doanh Thu | AJ2: Sum of Lợi Nhuận | AN2: Row Labels | AO2: Sum of Doanh Thu | AP2: Sum of Lợi Nhuận | AQ2: Margin % | AS2: BC KAKA NANO X6 x 20 x 15 lốc | AT2: 0.71428571 | AU2: 140000 | BA2: Giấy Vệ Sinh | BB2: 86484000 | BH2: Cần chú ý | BI2: 19.6 | BJ2: 173298
A3: Row Labels | B3: Tổng Doanh Thu | D3: Row Labels | E3: Tổng Lợi Nhuận | J3: Khách hàng Mới | K3: 25980700 | O3: Khách hàng Mới | P3: 32 | S3: Khách hàng Mới | T3: 25980700 | Z3: =TEXT(VLOOKUP("Grand Total", J12:L22, 3, FALSE), "0.00%") -> 17.43% | AA3: Bánh gạo TE Happy Bites Việt Quất 50g x 12 hộp | AB3: 5824000 | AH3: Khách hàng Cần chú ý | AI3: 52659100 | AJ3: 9358117 | AN3: A1 Yến đường phèn 70ml x 6 lọ x 6 hộp | AO3: 3360000 | AP3: 360000 | AQ3: =IF($AO$3=0,0,$AP$3/$AO$3) -> 0.10714286 | AS3: BC KaKa Nhật N82 bộ 3 cây x 9 bộ x 33 túi | AT3: 0.7037037 | AU3: 121500 | BA3: Khăn Giấy | BB3: 57804500 | BH3: Mới | BI3: 9.6 | BJ3: 324781
A4: Khăn ướt TE Villa 250g x 30 gói | B4: 5530000 | D4: Yến sào Seunest KĐ xanh x 6 hộp | E4: 3468000 | J4: Khách hàng Tiềm năng | K4: 5521000 | M4: =M2 -> 0.046250101 | O4: Khách hàng Tiềm năng | P4: 36 | S4: Khách hàng Tiềm năng | T4: 5521000 | AA4: HIMA DAILY (new) 6 lọ x 6 hộp | AB4: 6816000 | AH4: Khách hàng Mới | AI4: 25980700 | AJ4: 7145178 | AN4: BÀN CHẢI ĐÁNH RĂNG ION - AKIRA Hộp | AO4: 441600 | AP4: -230400 | AQ4: =IF($AO$4=0,0,$AP$4/$AO$4) -> -0.52173913 | AS4: BC KAKA NANO N302 x 20 cây x 20 hộp | AT4: 0.65437788 | AU4: 217000 | BA4: Chăm Sóc Nhà Cửa | BB4: 30979556 | BH4: Tiềm năng | BI4: 2.1 | BJ4: 87193
A5: Bánh gạo TE Happy Bites Chuối 50g x 12 hộp | B5: 5540000 | D5: Khăn Napkin Toply 100 tờ x 48 gói | E5: 5330600 | J5: Khách hàng Trung thành | K5: 102689500 | O5: Khách hàng Trung thành | P5: 338 | S5: Khách hàng Trung thành | T5: 102689500 | AA5: Khăn Napkin Fairy 320 x 100 tờ x 48 gói | AB5: 7874000 | AH5: Khách hàng Tiềm năng | AI5: 5521000 | AJ5: 1395083 | AN5: BÀN CHẢI ĐÁNH RĂNG ION - HARU | AO5: 217000 | AP5: -113000 | AQ5: =IF($AO$5=0,0,$AP$5/$AO$5) -> -0.52073733 | AS5: BC KAKA NANO N193 x 30 cây x 10 hộp | AT5: 0.63133641 | AU5: 217000 | BA5: Bánh Snack | BB5: 26660400 | BH5: Trung thành | BI5: 38.1 | BJ5: 420000
A6: Bánh gạo TE Happy Bites Việt Quất 50g x 12 hộp | B6: 5824000 | D6: Yến sào Seunest CĐ vàng x 6 hộp | E6: 9141000 | J6: Khách hàng VIP | K6: 82433156 | O6: Khách hàng VIP | P6: 172 | S6: Khách hàng VIP | T6: 82433156 | Z6: =TEXT(VLOOKUP("Grand Total", J1:K11, 2, FALSE) / VLOOKUP("Grand Total", O1:P11, 2, FALSE), "#,##0 ""VNĐ/đơn""") -> 381,962 VNĐ/đơn | AA6: Khăn Napkin TiOne nâu 100 tờ x 30 gói | AB6: 7914000 | AH6: Khách hàng Trung thành | AI6: 102689500 | AJ6: 19740013 | AN6: BÀN CHẢI ĐÁNH RĂNG ION - JEWEL | AO6: 150000 | AP6: -62500 | AQ6: =IF($AO$6=0,0,$AP$6/$AO$6) -> -0.41666667 | AS6: Khánh Hòa SmileNest Đỏ ( Canxi) 6 lọ x 8 hộp | AT6: 0.59166667 | AU6: 1920000 | BA6: Khăn Ướt | BB6: 19166000 | BH6: VIP | BI6: 30.6 | BJ6: 960258
A7: HIMA DAILY (new) 6 lọ x 6 hộp | B7: 6816000 | D7: Grand Total | E7: 17939600 | J7: Grand Total | K7: 269283456 | O7: Grand Total | P7: 705 | S7: Grand Total | T7: 269283456 | AA7: Khăn Napkin Toply 100 tờ x 48 gói | AB7: 14834600 | AH7: Khách hàng VIP | AI7: 82433156 | AJ7: 19205168 | AN7: BÀN CHẢI ĐÁNH RĂNG ION - OCEAN | AO7: 2070000 | AP7: -474000 | AQ7: =IF($AO$7=0,0,$AP$7/$AO$7) -> -0.22898551 | BA7: Thực Phẩm & Bánh Kẹo | BB7: 17603500
A8: Yến sào Finenest CĐ đỏ x 6 hộp | B8: 7732000 | AA8: Khăn ướt TE Villa 250g x 30 gói | AB8: 5530000 | AH8: Grand Total | AI8: 269283456 | AJ8: 56843559 | AN8: BÀN CHẢI ĐÁNH RĂNG ION - SILISON NANO | AO8: 762000 | AP8: -246000 | AQ8: =IF($AO$8=0,0,$AP$8/$AO$8) -> -0.32283465 | BA8: Bàn Chải & Răng Miệng | BB8: 12408100
A9: Khăn Napkin Fairy 320 x 100 tờ x 48 gói | B9: 7874000 | K9: =K3 -> 25980700 | P9: =P3 -> 32 | T9: =T3 -> 25980700 | AA9: Yến sào Finenest CĐ đỏ x 6 hộp | AB9: 7732000 | AN9: BÀN CHẢI ĐÁNH RĂNG ION- UNIQUE | AO9: 105000 | AP9: -55000 | AQ9: =IF($AO$9=0,0,$AP$9/$AO$9) -> -0.52380952 | BA9: Tăm Bông | BB9: 7857800
A10: Khăn Napkin TiOne nâu 100 tờ x 30 gói | B10: 7914000 | AA10: Yến sào Seunest CĐ vàng x 6 hộp | AB10: 23241000 | AN10: BÀN CHẢI ĐÁNH RĂNG TE ION - ELEPHAN | AO10: 540000 | AP10: 0 | AQ10: =IF($AO$10=0,0,$AP$10/$AO$10) -> 0 | BA10: Yến Sào & Sức Khỏe | BB10: 6208600
A11: Yến sào Seunest KĐ xanh x 6 hộp | B11: 8168000 | AA11: Yến sào Seunest KĐ xanh x 6 hộp | AB11: 8168000 | AN11: BÀN CHẢI ĐÁNH RĂNG TE ION - NEKO plus | AO11: 358000 | AP11: -142000 | AQ11: =IF($AO$11=0,0,$AP$11/$AO$11) -> -0.39664804 | BA11: Nước Uống | BB11: 2371000
A12: Khăn Napkin Toply 100 tờ x 48 gói | B12: 14834600 | J12: Row Labels | K12: Tổng Lợi Nhuận | L12: % Tỷ lệ lợi nhuận | O12: Row Labels | P12: Sum of Doanh Thu | S12: Row Labels | T12: Số Khách hàng | AA12: Grand Total | AB12: 93473600 | AN12: BÀN CHẢI ĐÁNH RĂNG TE ION - PANDA | AO12: 1070000 | AP12: -82000 | AQ12: =IF($AO$12=0,0,$AP$12/$AO$12) -> -0.076635514 | BA12: Mẹ & Bé | BB12: 1170000
A13: Yến sào Seunest CĐ vàng x 6 hộp | B13: 23241000 | D13: Row Labels | E13: TB % SL Khuyến mãi | F13: Tổng SL Xuất | G13: Tổng SL Xuất KM | J13: Khách hàng Cần chú ý | K13: 9358117 | L13: 0.19424004 | O13: Thế Giới Con Cưng - HCL | P13: 11022000 | S13: 9 | AN13: Bánh bông lan SHINO vị cốm 13 cái x 18 hộp | AO13: 384000 | AP13: 78000 | AQ13: =IF($AO$13=0,0,$AP$13/$AO$13) -> 0.203125 | BA13: Khác | BB13: 570000
A14: Grand Total | B14: 93473600 | D14: Bao | E14: 0 | F14: 15 | G14: 0 | J14: Khách hàng Mới | K14: 7145178 | L14: 0.17046093 | O14: Minh Hiền (chị Ớ) - B.H.Trung | P14: 10078000 | S14: Khách hàng Cần chú ý | T14: 33 | AN14: Bánh bông lan SHINO vị dâu 13 cái x 18 hộp | AO14: 384000 | AP14: 78000 | AQ14: =IF($AO$14=0,0,$AP$14/$AO$14) -> 0.203125 | BA14: Grand Total | BB14: 269283456
D15: Bịch | E15: 0.15873016 | F15: 32 | G15: 6 | J15: Khách hàng Tiềm năng | K15: 1395083 | L15: 0.12969009 | O15: Mẹ & Bé (Hồng Nhung) - M.Long | P15: 8626400 | S15: Khách hàng Mới | T15: 1 | AN15: Bánh bông lan SHINO vị sữa chua 13 cái x 18 hộp | AO15: 384000 | AP15: 78000 | AQ15: =IF($AO$15=0,0,$AP$15/$AO$15) -> 0.203125
D16: Bình | E16: 0.030701754 | F16: 70 | G16: 3 | J16: Khách hàng Trung thành | K16: 19740013 | L16: 0.15564753 | O16: Grand Total | P16: 29726400 | S16: Khách hàng Tiềm năng | T16: 1 | AN16: Bánh đũa Gap Dâu tây 12g x 12 hộp x 12 | AO16: 240000 | AP16: 29580 | AQ16: =IF($AO$16=0,0,$AP$16/$AO$16) -> 0.12325
D17: Block | E17: 0 | F17: 3 | G17: 0 | J17: Khách hàng VIP | K17: 19205168 | L17: 0.20633797 | S17: Khách hàng Trung thành | T17: 24 | AN17: Bánh đũa Gap Sô cô la 12g x 12 hộp x 12 | AO17: 288000 | AP17: 35496 | AQ17: =IF($AO$17=0,0,$AP$17/$AO$17) -> 0.12325
D18: Bộ | E18: 0.12142857 | F18: 21 | G18: 3 | J18: Grand Total | K18: 56843559 | L18: 0.17431358 | S18: Khách hàng VIP | T18: 17 | AN18: Bánh gạo Bin Bin Rong Biển 150g x 20 gói | AO18: 192000 | AP18: 25680 | AQ18: =IF($AO$18=0,0,$AP$18/$AO$18) -> 0.13375
D19: Cái | E19: 0.0046382189 | F19: 510 | G19: 5 | S19: 10 | AN19: Bánh gạo Bin Bin Tuyết Cay 145g x 20 gói | AO19: 212000 | AP19: 24032 | AQ19: =IF($AO$19=0,0,$AP$19/$AO$19) -> 0.11335849
D20: Cây | E20: 0.04524457 | F20: 1142 | G20: 65 | K20: =K14 -> 7145178 | L20: =L14 -> 0.17046093 | S20: Khách hàng Cần chú ý | T20: 30 | AN20: Bánh gạo TE Happy Bites Chuối 50g x 12 hộp | AO20: 5540000 | AP20: 149300 | AQ20: =IF($AO$20=0,0,$AP$20/$AO$20) -> 0.026949458
A21: Row Labels | B21: Tổng Doanh Thu | D21: Chai | E21: 0.042430186 | F21: 739 | G21: 45 | S21: Khách hàng Mới | T21: 2 | AN21: Bánh gạo TE Happy Bites Táo 50g x 12 hộp | AO21: 5202000 | AP21: -7500 | AQ21: =IF($AO$21=0,0,$AP$21/$AO$21) -> -0.0014417532
A22: 10 | B22: 79300016 | D22: Cuộn | E22: 0.083333333 | F22: 20 | G22: 2 | S22: Khách hàng Tiềm năng | T22: 8 | AN22: Bánh gạo TE Happy Bites Việt Quất 50g x 12 hộp | AO22: 5824000 | AP22: -336800 | AQ22: =IF($AO$22=0,0,$AP$22/$AO$22) -> -0.05782967
A23: Grand Total | B23: 79300016 | D23: Dây | E23: 0.0068027211 | F23: 132 | G23: 2 | J23: Row Labels | K23: SL Khách hàng | S23: Khách hàng Trung thành | T23: 27 | AN23: Bánh quy WINWIN - Hương vị BẮP (943) 8 gói x 180g x 24 hộp | AO23: 84000 | AP23: 1500 | AQ23: =IF($AO$23=0,0,$AP$23/$AO$23) -> 0.017857143
D24: Gói | E24: 0.023120945 | F24: 6894 | G24: 208 | J24: Khách hàng Cần chú ý | K24: 54 | S24: Khách hàng VIP | T24: 13 | AN24: Bánh quy WINWIN - Hương vị HẢI SẢN (997) 8 gói x 18g x 24 hộp | AO24: 84000 | AP24: 1500 | AQ24: =IF($AO$24=0,0,$AP$24/$AO$24) -> 0.017857143
D25: Hộp | E25: 0.089980359 | F25: 1513 | G25: 232 | J25: Khách hàng Mới | K25: 22 | S25: 11 | AN25: Bánh quy WINWIN - Khoai tây vị BBQ (908) 8 gói x 20g x 24 hộp | AO25: 84000 | AP25: 1500 | AQ25: =IF($AO$25=0,0,$AP$25/$AO$25) -> 0.017857143
D26: Hủ | E26: 0 | F26: 17 | G26: 0 | J26: Khách hàng Tiềm năng | K26: 16 | S26: Khách hàng Mới | T26: 22 | AN26: Bánh quy WINWIN - Khoai tây vị RAU CẢI (910) 8 gói x 20g x 24 hộp | AO26: 84000 | AP26: 1500 | AQ26: =IF($AO$26=0,0,$AP$26/$AO$26) -> 0.017857143
D27: Lon | E27: 0 | F27: 151 | G27: 0 | J27: Khách hàng Trung thành | K27: 47 | S27: Khách hàng Tiềm năng | T27: 8 | AN27: Bánh SOGI CHOCOLATE 12g x 24 cây x 6 hủ | AO27: 434000 | AP27: 56000 | AQ27: =IF($AO$27=0,0,$AP$27/$AO$27) -> 0.12903226
D28: Thùng | E28: 0 | F28: 14 | G28: 0 | J28: Khách hàng VIP | K28: 20 | S28: Khách hàng Trung thành | T28: 42 | AN28: Bánh SOGI CHOCOLATE WITH STRAWBERRY CREAM 12g x 24 cây x 6 hủ | AO28: 285000 | AP28: 33000 | AQ28: =IF($AO$28=0,0,$AP$28/$AO$28) -> 0.11578947
D29: Túi | E29: 0.064027379 | F29: 409 | G29: 61 | J29: Grand Total | K29: 159 | S29: Khách hàng VIP | T29: 20 | AN29: Bánh TE Munchies Chuối & Bí Đỏ 30g x 12 hộp | AO29: 2021200 | AP29: 120400 | AQ29: =IF($AO$29=0,0,$AP$29/$AO$29) -> 0.059568573
D30: Vỉ | E30: 0.022222222 | F30: 13 | G30: 1 | S30: Grand Total | T30: 159 | AN30: Bánh TE Munchies Mâm Xôi & Củ Dền 30g x 12 hộp | AO30: 1861200 | AP30: -39600 | AQ30: =IF($AO$30=0,0,$AP$30/$AO$30) -> -0.021276596
D31: Grand Total | E31: 0.046250101 | F31: 11695 | G31: 633 | K31: =K25 -> 22 | AN31: Bánh xốp Papang vị Cam 350g x 12 | AO31: 402000 | AP31: 58800 | AQ31: =IF($AO$31=0,0,$AP$31/$AO$31) -> 0.14626866
AN32: Bánh xốp Papang vị Chocolate 350g x 12 | AO32: 335000 | AP32: 49000 | AQ32: =IF($AO$32=0,0,$AP$32/$AO$32) -> 0.14626866
AN33: Bánh xốp Papang vị Sữa 350g x 12 | AO33: 402000 | AP33: 58800 | AQ33: =IF($AO$33=0,0,$AP$33/$AO$33) -> 0.14626866
AN34: Bánh xốp Uni Chocolate 288g x 12 | AO34: 147000 | AP34: 21600 | AQ34: =IF($AO$34=0,0,$AP$34/$AO$34) -> 0.14693878
AN35: Bánh xốp Uni Vanila 288g x 12 | AO35: 147000 | AP35: 21600 | AQ35: =IF($AO$35=0,0,$AP$35/$AO$35) -> 0.14693878
AN36: BC AquaStar AQ-01 24 cây x 20 hộp | AO36: 140000 | AP36: -16400 | AQ36: =IF($AO$36=0,0,$AP$36/$AO$36) -> -0.11714286
AN37: BC Ion Eco care (NK Hàn Quốc) 48 cây x 2 hộp | AO37: 150000 | AP37: -20200 | AQ37: =IF($AO$37=0,0,$AP$37/$AO$37) -> -0.13466667
AN38: BC Ion Exciting lông xoắn kép 24 cây x 1 hộp | AO38: 105000 | AP38: -5400 | AQ38: =IF($AO$38=0,0,$AP$38/$AO$38) -> -0.051428571
AN39: BC KAKA NANO N189 x 30 x 10 hộp | AO39: 630000 | AP39: 198000 | AQ39: =IF($AO$39=0,0,$AP$39/$AO$39) -> 0.31428571
AN40: BC KAKA NANO N193 x 30 cây x 10 hộp | AO40: 217000 | AP40: 137000 | AQ40: =IF($AO$40=0,0,$AP$40/$AO$40) -> 0.63133641
...

Sheet Customer Pivot
A1: Row Labels | B1: Tổng Doanh Thu | D1: % KM Trung Bình | F1: Row Labels | G1: Số Đơn Hàng | J1: Row Labels | K1: Tổng Doanh Thu | Y1: [Measures].[Sum of Doanh Thu] | Z1: =TEXT(VLOOKUP("Grand Total", 'Customer Pivot'!$A$1:$B$11, 2, FALSE), "#,##0 ""VNĐ""") -> 269,283,456 VNĐ
A2: Khách hàng Cần chú ý | B2: 52659100 | D2: 0.046250101 | F2: Khách hàng Cần chú ý | G2: 127 | J2: Khách hàng Cần chú ý | K2: 52659100 | Y2: [Measures].[Distinct Count of Khách hàng] | Z2: =TEXT(VLOOKUP("Grand Total", 'Customer Pivot'!$A$12:$C$22, 2, FALSE), "#,##0 ""VNĐ""") -> 56,843,559 VNĐ
A3: Khách hàng Mới | B3: 25980700 | F3: Khách hàng Mới | G3: 32 | J3: Khách hàng Mới | K3: 25980700 | Y3: [Measures].[Average of % SL Khuyến mãi] | Z3: =TEXT(VLOOKUP("Grand Total", 'Customer Pivot'!$A$12:$C$22, 3, FALSE), "0.00%") -> 17.43%
A4: Khách hàng Tiềm năng | B4: 5521000 | D4: =D2 -> 0.046250101 | F4: Khách hàng Tiềm năng | G4: 36 | J4: Khách hàng Tiềm năng | K4: 5521000 | Y4: [Measures].[Distinct Count of Khách hàng] | Z4: =TEXT(VLOOKUP("Grand Total", 'Customer Pivot'!$F$1:$G$11, 2, FALSE), "#,##0 ""đơn""") -> 705 đơn
A5: Khách hàng Trung thành | B5: 102689500 | F5: Khách hàng Trung thành | G5: 338 | J5: Khách hàng Trung thành | K5: 102689500 | Y5: [Measures].[Sum of Lợi Nhuận] | Z5: =TEXT(VLOOKUP("Grand Total", 'Customer Pivot'!$A$23:$B$33, 2, FALSE), "#,##0 ""khách""") -> 159 khách
A6: Khách hàng VIP | B6: 82433156 | F6: Khách hàng VIP | G6: 172 | J6: Khách hàng VIP | K6: 82433156 | Y6: [Measures].[Count of STT] | Z6: =TEXT(VLOOKUP("Grand Total", 'Customer Pivot'!$A$1:$B$11, 2, FALSE) / VLOOKUP("Grand Total", 'Customer Pivot'!$F$1:$G$11, 2, FALSE), "#,##0 ""VNĐ/đơn""") -> 381,962 VNĐ/đơn
A7: Grand Total | B7: 269283456 | F7: Grand Total | G7: 705 | J7: Grand Total | K7: 269283456
B9: =B3 -> 25980700 | G9: =G3 -> 32 | K9: =K3 -> 25980700
Z10: =GETPIVOTDATA("[Measures].[Sum of Doanh Thu]", $A$1) -> 269283456 | AA10: Khách hàng | AB10: Doanh Thu
AA11: Chú 7 Vân - B.H.Tây | AB11: 7758000
A12: Row Labels | B12: Tổng Lợi Nhuận | C12: % Tỷ lệ lợi nhuận | F12: Row Labels | G12: Sum of Doanh Thu | J12: Row Labels | K12: Số Khách hàng | AA12: Ngọc Khánh ( Mỹ Khánh ) - M.Trắng | AB12: 5321000
A13: Khách hàng Cần chú ý | B13: 9358117 | C13: 0.19424004 | F13: Thế Giới Con Cưng - HCL | G13: 11022000 | J13: 9 | AA13: Thế Giới Con Cưng - HCL | AB13: 4965000
A14: Khách hàng Mới | B14: 7145178 | C14: 0.17046093 | F14: Minh Hiền (chị Ớ) - B.H.Trung | G14: 10078000 | J14: Khách hàng Cần chú ý | K14: 33 | AA14: Căn tin BV Phổi( Chị Duyên) - BV phổi | AB14: 3744000
A15: Khách hàng Tiềm năng | B15: 1395083 | C15: 0.12969009 | F15: Mẹ & Bé (Hồng Nhung) - M.Long | G15: 8626400 | J15: Khách hàng Mới | K15: 1 | AA15: Kim Hường - B.H.Tây | AB15: 3360000
A16: Khách hàng Trung thành | B16: 19740013 | C16: 0.15564753 | F16: Chú 7 Vân - B.H.Tây | G16: 8520000 | J16: Khách hàng Tiềm năng | K16: 1 | AA16: TT Hoàng Yến - M.Long | AB16: 3014400
A17: Khách hàng VIP | B17: 19205168 | C17: 0.20633797 | F17: Căn tin BV Phổi( Chị Duyên) - BV phổi | G17: 8334000 | J17: Khách hàng Trung thành | K17: 24 | AA17: Hoàng Huyên - M.Long | AB17: 2995000
A18: Grand Total | B18: 56843559 | C18: 0.17431358 | F18: Grand Total | G18: 46580400 | J18: Khách hàng VIP | K18: 17 | AA18: MP Nhanh - M.Hiệp | AB18: 2598000
J19: 10 | AA19: Minh Hiền (chị Ớ) - B.H.Trung | AB19: 2360000
B20: =B14 -> 7145178 | C20: =C14 -> 0.17046093 | J20: Khách hàng Cần chú ý | K20: 30 | AA20: Xuân Bình - M.Hiệp | AB20: 2136840
J21: Khách hàng Mới | K21: 2
J22: Khách hàng Tiềm năng | K22: 8
A23: Row Labels | B23: SL Khách hàng | J23: Khách hàng Trung thành | K23: 27
A24: Khách hàng Cần chú ý | B24: 54 | J24: Khách hàng VIP | K24: 13
A25: Khách hàng Mới | B25: 22 | J25: 11
A26: Khách hàng Tiềm năng | B26: 16 | J26: Khách hàng Mới | K26: 22
A27: Khách hàng Trung thành | B27: 47 | J27: Khách hàng Tiềm năng | K27: 8
A28: Khách hàng VIP | B28: 20 | J28: Khách hàng Trung thành | K28: 42
A29: Grand Total | B29: 159 | J29: Khách hàng VIP | K29: 20
J30: Grand Total | K30: 159
B31: =B25 -> 22

Sheet RFM Table
A1: Khách hàng | B1: Ngày mua cuối | C1: Số lần mua | D1: Tổng tiền | E1: R | F1: F | G1: M | H1: Mã RFM | I1: Segment
A2: 4 Xinh - M.Trắng | B2: 45213 | C2: 3 | D2: 1034000 | E2: 2 | F2: 3 | G2: 3 | H2: 233 | I2: Khách hàng Cần chú ý
A3: 4 Điều - M.Trắng | B3: 45185 | C3: 1 | D3: 360000 | E3: 1 | F3: 1 | G3: 2 | H3: 112 | I3: Khách hàng Cần chú ý
A4: 5 Bún - P.Thịnh | B4: 45260 | C4: 3 | D4: 445000 | E4: 5 | F4: 3 | G4: 2 | H4: 532 | I4: Khách hàng Trung thành
A5: 5 Hiếu - T.Linh | B5: 45226 | C5: 1 | D5: 360000 | E5: 2 | F5: 1 | G5: 2 | H5: 212 | I5: Khách hàng Cần chú ý
A6: 5 Phụng - T.Nghĩa | B6: 45239 | C6: 12 | D6: 3277000 | E6: 3 | F6: 5 | G6: 5 | H6: 355 | I6: Khách hàng Trung thành
A7: 6 Trạng - M.Trắng | B7: 45213 | C7: 5 | D7: 1941000 | E7: 2 | F7: 4 | G7: 4 | H7: 244 | I7: Khách hàng Cần chú ý
A8: 8 Kịp - P.Thịnh | B8: 45260 | C8: 3 | D8: 520000 | E8: 5 | F8: 3 | G8: 2 | H8: 532 | I8: Khách hàng Trung thành
A9: 9 Tiến - M.Trắng | B9: 45213 | C9: 1 | D9: 312000 | E9: 2 | F9: 1 | G9: 2 | H9: 212 | I9: Khách hàng Cần chú ý
A10: An Nhiên - T.Nghĩa | B10: 45239 | C10: 10 | D10: 1022000 | E10: 3 | F10: 5 | G10: 3 | H10: 353 | I10: Khách hàng Trung thành
A11: Anh Dũng - HCL (Thanh Mỹ) | B11: 45243 | C11: 2 | D11: 275000 | E11: 4 | F11: 2 | G11: 1 | H11: 421 | I11: Khách hàng Mới
A12: Anh Nghiệp (Cậu 2 Nhựt) - Ngã 4 | B12: 45183 | C12: 2 | D12: 734000 | E12: 1 | F12: 2 | G12: 3 | H12: 123 | I12: Khách hàng Cần chú ý
A13: Anh Như - Chợ 307 | B13: 45243 | C13: 2 | D13: 612000 | E13: 4 | F13: 2 | G13: 2 | H13: 422 | I13: Khách hàng Mới
... A160: Đạt Hường - P.Thịnh | B160: 45198 | C160: 3 | D160: 981000 | E160: 1 | F160: 3 | G160: 3 | H160: 133 | I160: Khách hàng Cần chú ý

Sheet Pivot Khách Hàng
A1: Khách hàng | B1: Ngày mua cuối | C1: Số đơn hàng | D1: Tổng tiền xuất | E1: Tổng lợi nhuận | F1: Tỷ lệ LN | G1: Segment | H1: Mã RFM
A2: Thế Giới Con Cưng - HCL | B2: 45250 | C2: 19 | D2: 11022000 | E2: 1446794 | F2: 0.1312642 | G2: Khách hàng Trung thành | H2: 455
A3: Minh Hiền (chị Ớ) - B.H.Trung | B3: 45255 | C3: 8 | D3: 10078000 | E3: 3570960 | F3: 0.35433221 | G3: Khách hàng VIP | H3: 555
A4: Mẹ & Bé (Hồng Nhung) - M.Long | B4: 45213 | C4: 5 | D4: 8626400 | E4: -431200 | F4: -0.049986089 | G4: Khách hàng Cần chú ý | H4: 245
A5: Chú 7 Vân - B.H.Tây | B5: 45255 | C5: 7 | D5: 8520000 | E5: 2454984 | F5: 0.28814366 | G5: Khách hàng VIP | H5: 545
A6: Căn tin BV Phổi( Chị Duyên) - BV phổi | B6: 45254 | C6: 7 | D6: 8334000 | E6: 1971276 | F6: 0.2365342 | G6: Khách hàng VIP | H6: 545
A7: Cẩm Giang - M.Xương | B7: 45255 | C7: 10 | D7: 7566000 | E7: 2282916 | F7: 0.30173354 | G7: Khách hàng VIP | H7: 555
A8: TT Hoàng Yến - M.Long | B8: 45236 | C8: 6 | D8: 6357600 | E8: 1013184 | F8: 0.1593658 | G8: Khách hàng Trung thành | H8: 345
A9: Thu Thủy - P.Mỹ (cầu Trâu Trắng) | B9: 45254 | C9: 11 | D9: 6324500 | E9: 807972 | F9: 0.12775271 | G9: Khách hàng VIP | H9: 555
A10: Hoàng Huyên - M.Long | B10: 45236 | C10: 3 | D10: 5907000 | E10: 720720 | F10: 0.12201117 | G10: Khách hàng Trung thành | H10: 335
A11: Ngọc Khánh ( Mỹ Khánh ) - M.Trắng | B11: 45185 | C11: 8 | D11: 5321000 | E11: 2183000 | F11: 0.41026123 | G11: Khách hàng Cần chú ý | H11: 155
A12: Xuân Bình - M.Hiệp | B12: 45255 | C12: 7 | D12: 5092056 | E12: 1188000 | F12: 0.23330458 | G12: Khách hàng VIP | H12: 555
A13: MP Nhanh - M.Hiệp | B13: 45255 | C13: 8 | D13: 4873000 | E13: -150440 | F13: -0.030872153 | G13: Khách hàng VIP | H13: 555
... A160: TT Mỹ Hạnh - T.H.Trung | B160: 45227 | C160: 1 | D160: 54000 | E160: -6378 | F160: -0.11811111 | G160: Khách hàng Tiềm năng | H160: 311

Sheet Segment Overview
A1: Segment | B1: Số khách hàng | C1: Tổng doanh thu
A2: Khách hàng VIP | B2: 20 | C2: 82433156
A3: Khách hàng Trung thành | B3: 47 | C3: 102689500
A4: Khách hàng Tiềm năng | B4: 16 | C4: 5521000
A5: Khách hàng Mới | B5: 22 | C5: 25980700
A6: Khách hàng Cần chú ý | B6: 54 | C6: 52659100
A7: Grand Total | B7: 159 | C7: 269283456

Sheet Log GD Ghi Giảm KM
A1: STT | B1: Mã | C1: Hàng | D1: SL KM thu hồi | E1: Tiền ghi giảm | F1: Ngày | G1: Khách hàng
A2: 9 | B2: KV1003 | C2: Khăn vuông TiOne xanh 100 tờ X 30 gói | D2: 10 | E2: -90000 | F2: 45173 | G2: Chị Nga - HCL
A3: 13 | B3: KV320 | C3: Khăn Napkin Fairy 320 x 100 tờ x 48 gói | D3: 6 | E3: -60000 | F3: 45173 | G3: Điện thoại Tuấn - N.Mỹ
A4: 23 | B4: KMQCT | C4: Quạt SENKO 1216 chân thấp | D4: 1 | E4: -233000 | F4: 45173 | G4: Chị Tuyết - HCL (N.Mỹ)
A5: 37 | B5: NG5000 | C5: Nước giặt Kimono 6 in 1 vuông (tím) 5Kg x 4 bình | D5: 4 | E5: -600000 | F5: 45180 | G5: Minh Hiền (chị Ớ) - B.H.Trung
A6: 121 | B6: HM610 | C6: Yến sào Finenest CĐ đỏ x 6 hộp | D6: 6 | E6: -720000 | F6: 45185 | G6: TH Ngân (chị Ngân) - T.H.Trung
A7: 131 | B7: HM607 | C7: Yến sào Seunest KĐ xanh x 6 hộp | D7: 6 | E7: -720000 | F7: 45185 | G7: Chú 7 Vân - B.H.Tây
A8: 132 | B8: HM608 | C8: Yến sào Seunest CĐ vàng x 6 hộp | D8: 6 | E8: -720000 | F8: 45185 | G8: Chú 7 Vân - B.H.Tây
A9: 145 | B9: KMNL7731 | C9: Nồi lẩu điện Comet 7731 | D9: 1 | E9: -370000 | F9: 45185 | G9: Thế Giới Con Cưng - HCL
A10: 154 | B10: HM607 | C10: Yến sào Seunest KĐ xanh x 6 hộp | D10: 6 | E10: -720000 | F10: 45185 | G10: Ngọc Khánh ( Mỹ Khánh ) - M.Trắng
A11: 155 | B11: HM608 | C11: Yến sào Seunest CĐ vàng x 6 hộp | D11: 12 | E11: -1440000 | F11: 45185 | G11: Ngọc Khánh ( Mỹ Khánh ) - M.Trắng
A12: 176 | B12: KMBTIGER | C12: Bia Tiger lon | D12: 1 | E12: -375000 | F12: 45192 | G12: Kim Hường - B.H.Tây
A13: 186 | B13: HM607 | C13: Yến sào Seunest KĐ xanh x 6 hộp | D13: 6 | E13: -660000 | F13: 45192 | G13: Tố Quyên - T.H.Trung
... A58: 829 | B58: HM613 | C58: HIMA Seunest DTHT có đường 6 lọ x 6 hộp | D58: 1 | E58: -130000 | F58: 45260 | G58: TT Chị Điệp - P.Thịnh
A60: ⚠️ Các dòng này là hàng KM bị thu hồi / chiết khấu ghi giảm. Tiền âm = giảm trừ doanh thu. KHÔNG tính vào SL bán thực tế.

Sheet ⚠️ Cần Review
A1: STT | B1: Mã | C1: Hàng | D1: ĐVT | E1: Tiền Nhập | F1: SL Xuất KM | G1: SL Xuất | H1: Tiền Xuất | I1: Doanh Thu | J1: Ngày Xuất | K1: Khách hàng | L1: Loại_GD
A2: 52 | B2: A1Y601 | C2: A1 Yến sào có nhân sâm 70ml x 6 lọ x 6 hộp | D2: Hộp | E2: 0 | F2: 1 | G2: 0 | H2: 0 | I2: 0 | J2: 45180 | K2: Vương Quốc Sữa - B.H.Trung | L2: KM_CHUA_CO_GIA
A3: 98 | B3: JA1KG | C3: Javel 1L x 12 chai | D3: Chai | E3: 0 | F3: 2 | G3: 0 | H3: 0 | I3: 0 | J3: 45184 | K3: Đạt Hường - P.Thịnh | L3: KM_CHUA_CO_GIA
A4: 251 | B4: KMNL7731 | C4: Nồi lẩu điện Comet 7731 | D4: Cái | E4: 0 | F4: 1 | G4: 0 | H4: 0 | I4: 0 | J4: 45199 | K4: Thế Giới Con Cưng - HCL | L4: KM_CHUA_CO_GIA
A5: 332 | B5: NRC1500 | C5: NRC 107 - 1,5L x 8 bình | D5: Bình | E5: 0 | F5: 1 | G5: 0 | H5: 0 | I5: 0 | J5: 45212 | K5: Ngọc Thắm - T.Nghĩa | L5: KM_CHUA_CO_GIA
A6: 403 | B6: HTBTE50 | C6: Bánh gạo TE Happy Bites Việt Quất 50g x 12 hộp | D6: Hộp | E6: 135900 | F6: 4 | G6: 3 | H6: -25000 | I6: -160900 | J6: 45220 | K6: Mẹ & Bé ( Mẹ Yêu Con) - M.Hiệp | L6: LOI_NHAP_LIEU
A7: 590 | B7: KMQ | C7: Quạt chân cao | D7: Cây | E7: 0 | F7: 1 | G7: 0 | H7: 0 | I7: 0 | J7: 45239 | K7: Chị Nhung - T.Nghĩa | L7: KM_CHUA_CO_GIA
A8: 635 | B8: KMQ | C8: Quạt chân cao | D8: Cây | E8: 0 | F8: 1 | G8: 0 | H8: 0 | I8: 0 | J8: 45243 | K8: Trung Phụng - T.H.Trung | L8: KM_CHUA_CO_GIA
A9: 775 | B9: HM110 | C9: Yến sào Finenest Saffron (hoa nghệ tây) x 10 hộp | D9: Hộp | E9: 0 | F9: 1 | G9: 0 | H9: 0 | I9: 0 | J9: 45255 | K9: Chị Thắm (Hồng Thắm) - B.H.Tây | L9: KM_CHUA_CO_GIA
A10: 797 | B10: KMBN | C10: Bộ nồi 3 cái | D10: Bộ | E10: 0 | F10: 1 | G10: 0 | H10: 0 | I10: 0 | J10: 45255 | K10: Tuấn Kiệt - M.Long | L10: KM_CHUA_CO_GIA
A12: ⚠️ KM_CHUA_CO_GIA: hàng KM có số lượng nhưng chưa có giá — cần bổ sung. | LOI_NHAP_LIEU: SL Xuất > 0 nhưng Tiền Xuất âm — cần xác nhận lại với người nhập liệu.
